Workbook

Sheet Backlog
A1: ID | B1: Epica | C1: Titulo | D1: Historia de Usuario | E1: Criterios de Aceptacion | F1: Prioridad | G1: Estimacion | H1: Estado | I1: Release | J1: Notas Tecnicas
A2: ING-01 | B2: Ingesta y Deteccion | C2: Conexion RTSP a camaras IP | D2: Como sistema, quiero conectarme a cada camara via RTSP para procesar su stream de video. | E2: Soporta URL con user:pass; reconecta si se cae; loguea estado. | F2: P0 | G2: M | H2: Hecho | I2: v0.1 MVP | J2: detector.py - implementado con OpenCV.
A3: ING-02 | B3: Ingesta y Deteccion | C3: Soporte dual: RTSP nativo + MediaMTX | D3: Como usuario, quiero elegir entre RTSP directo o proxy MediaMTX para camaras inestables. | E3: Flag modo_hw; fallback automatico a ip_respaldo; config en DB. | F3: P0 | G3: M | H3: Hecho | I3: v0.1 MVP
A4: ING-03 | B4: Ingesta y Deteccion | C4: Deteccion de personas con YOLO | D4: Como sistema, quiero detectar personas en cada frame para decidir si disparar analisis profundo. | E4: Modelo YOLOv8; bbox + confianza + track_id; filtrar por clase 'person'. | F4: P0 | G4: L | H4: Hecho | I4: v0.1 MVP | J4: yolo_detector.py - usa ultralytics.
A5: ING-04 | B5: Ingesta y Deteccion | C5: Multi-camara en paralelo | D5: Como usuario, quiero monitorear multiples camaras simultaneamente sin degradacion. | E5: Un thread por camara; misma GPU compartida; no se bloquean entre si. | F5: P0 | G5: M | H5: Hecho | I5: v0.1 MVP
A6: ING-05 | B6: Ingesta y Deteccion | C6: Reconexion automatica | D6: Como sistema, quiero recuperarme solo si una camara se desconecta temporalmente. | E6: Backoff exponencial; log de caida y reconexion; marca estado_salud. | F6: P0 | G6: S | H6: Hecho | I6: v0.1 MVP
A7: ING-06 | B7: Ingesta y Deteccion | C7: Anti-duplicados con track_id | D7: Como sistema, no quiero disparar LLaVA mil veces por la misma persona cruzando camara. | E7: track_id de YOLO persiste por N frames; solo nuevos tracks disparan analisis. | F7: P0 | G7: M | H7: Hecho | I7: v0.1 MVP
A8: ING-07 | B8: Ingesta y Deteccion | C8: Detectar mas clases (vehiculos, paquetes) | D8: Como usuario, quiero detectar autos, motos y paquetes abandonados, no solo personas. | E8: Config por camara de clases permitidas; prompts LLaVA adaptados. | F8: P2 | G8: M | H8: Pendiente | I8: v0.3 | J8: YOLO ya los detecta; solo falta filtro + prompt.
A9: ING-08 | B9: Ingesta y Deteccion | C9: Zonas de interes (poligonal masking) | D9: Como usuario, quiero ignorar partes del frame (calle publica) y alertar solo en zonas privadas. | E9: UI para dibujar poligono sobre preview; detecciones fuera = descartadas. | F9: P1 | G9: L | H9: Pendiente | I9: v0.2 | J9: Necesita frontend editor de poligonos.
A10: ING-09 | B10: Ingesta y Deteccion | C10: Deteccion de eventos especiales | D10: Como usuario, quiero detectar caidas, aglomeraciones o actitudes agresivas. | E10: Modelos especificos (pose estimation); clasificador por evento; integracion con alertas. | F10: P3 | G10: XL | H10: Pendiente | I10: v1.0 | J10: Requiere investigacion de modelos.
A11: ING-10 | B11: Ingesta y Deteccion | C11: Auto-discovery ONVIF | D11: Como admin, quiero que el sistema encuentre camaras nuevas en la red sin configurarlas a mano. | E11: Scan de red; descubre dispositivos ONVIF; muestra UI para importarlas. | F11: P2 | G11: L | H11: Pendiente | I11: v0.4
A12: IA-01 | B12: Analisis IA | C12: Integracion con Ollama local | D12: Como sistema, quiero correr LLaVA localmente sin depender de APIs externas. | E12: Ollama API HTTP; timeout; manejo de errores; fallback si no responde. | F12: P0 | G12: M | H12: Hecho | I12: v0.1 MVP | J12: analizador.py y analizador2.py.
A13: IA-02 | B13: Analisis IA | C13: Dos analizadores (rapido vs preciso) | D13: Como usuario, quiero elegir entre analisis rapido (llava:7b) o preciso (llava:13b/34b). | E13: Flag en .env CAMARAS_ANALIZADOR; misma API publica entre v1 y v2. | F13: P0 | G13: S | H13: Hecho | I13: v0.1 MVP
A14: IA-03 | B14: Analisis IA | C14: Cola FIFO para serializar llamadas LLaVA | D14: Como sistema, no quiero saturar la GPU con analisis concurrentes; deben procesarse de a uno. | E14: queue.Queue(maxsize=5); descarta si llena; log de cola saturada. | F14: P0 | G14: M | H14: Hecho | I14: v0.1 MVP | J14: En clase AnalizadorAsync del detector.
A15: IA-04 | B15: Analisis IA | C15: Prompts contextuales por zona | D15: Como usuario, quiero que LLaVA sepa si la camara es ingreso, patio o almacen para analizar mejor. | E15: Campo contexto_zona por camara; se incluye en el prompt del LLM. | F15: P0 | G15: S | H15: Hecho | I15: v0.1 MVP
A16: IA-05 | B16: Analisis IA | C16: Soporte Llama 3.2 Vision / GPT-4V | D16: Como usuario, quiero poder elegir modelos nuevos cuando salen, sin reescribir el codigo. | E16: Adapter pattern; config de modelo en DB; A/B testing entre modelos. | F16: P2 | G16: L | H16: Pendiente | I16: v0.4
A17: IA-06 | B17: Analisis IA | C17: Cache semantico de analisis similares | D17: Como sistema, quiero evitar re-analizar escenas visualmente similares a las recientes. | E17: Embedding del frame; similitud coseno > 0.95 => devuelve analisis cacheado. | F17: P3 | G17: XL | H17: Pendiente | I17: v1.0 | J17: Complejo; requiere modelo de embeddings.
A18: IA-07 | B18: Analisis IA | C18: Fine-tuning con dataset propio | D18: Como producto, quiero un modelo ajustado a nuestras camaras para reducir falsos positivos. | E18: Dataset etiquetado; pipeline de entrenamiento; A/B contra modelo base. | F18: P3 | G18: XL | H18: Pendiente | I18: v1.5
A19: STG-01 | B19: Storage | C19: Upload de snapshots a MinIO | D19: Como sistema, quiero persistir imagenes de alertas en storage S3-compatible. | E19: boto3; organizacion por YYYY/MM/DD/camara/uuid.jpg; metadata. | F19: P0 | G19: M | H19: Hecho | I19: v0.1 MVP | J19: storage.py.
A20: STG-02 | B20: Storage | C20: URLs presignadas para frontend | D20: Como frontend, quiero mostrar imagenes sin necesitar credenciales de MinIO. | E20: GET /alertas/{id}/snapshot con redirect 302 a URL temporal. | F20: P0 | G20: S | H20: Hecho | I20: v0.1 MVP
A21: STG-03 | B21: Storage | C21: Degradacion graciosa si MinIO cae | D21: Como sistema, quiero seguir disparando alertas aunque el storage este caido. | E21: Errores de upload no tiran el detector; se loguea y se continua. | F21: P0 | G21: S | H21: Hecho | I21: v0.1 MVP
A22: STG-04 | B22: Storage | C22: Politica de retencion (lifecycle) | D22: Como admin, quiero que snapshots de mas de 30 dias se borren automaticamente. | E22: Lifecycle rule en MinIO; configurable por .env. | F22: P1 | G22: S | H22: Pendiente | I22: v0.2 | J22: Sin esto el disco se llena solo.
A23: STG-05 | B23: Storage | C23: Backup a cold storage | D23: Como admin, quiero mover snapshots viejos (>90 dias) a storage barato o externo. | E23: S3 Glacier o similar; transparente para la API. | F23: P2 | G23: M | H23: Pendiente | I23: v0.4
A24: STG-06 | B24: Storage | C24: Compresion inteligente | D24: Como sistema, quiero reducir el tamano de snapshots sin perder calidad. | E24: JPG quality configurable; WebP como alternativa; comparativa de tamano. | F24: P2 | G24: S | H24: Pendiente | I24: v0.3
A25: STG-07 | B25: Storage | C25: Sincronizacion hibrida con AWS S3 | D25: Como producto, quiero que el dia de mudarme a la nube sea solo cambiar una URL. | E25: Codigo ya usa boto3; solo cambiar endpoint + credenciales. | F25: P2 | G25: S | H25: Pendiente | I25: v0.5 | J25: Ya compatible, falta documentar.
A26: RT-01 | B26: Cache y Realtime | C26: Cliente Redis con degradacion graciosa | D26: Como sistema, quiero que si Redis cae, la API y el detector sigan andando. | E26: Wrapper singleton; decorador @_safe; heartbeat offline/online. | F26: P0 | G26: M | H26: Hecho | I26: v0.2 Redis | J26: redis_cache.py.
A27: RT-02 | B27: Cache y Realtime | C27: Cooldown inteligente TTL variable | D27: Como sistema, no quiero disparar LLaVA en escenas repetidas; el cooldown debe ser corto si la escena es peligrosa. | E27: TTL: alto=15s, medio=30s, bajo=60s; bypass si cantidad de personas cambia. | F27: P0 | G27: M | H27: Hecho | I27: v0.2 Redis | J27: 'Opcion C' - 3 condiciones de skip.
A28: RT-03 | B28: Cache y Realtime | C28: Estado en vivo por camara | D28: Como API, quiero poder decirle al frontend que esta pasando AHORA en cada camara sin tocar Postgres. | E28: set_estado_camara + get/listar con TTL 5 min. | F28: P0 | G28: S | H28: Hecho | I28: v0.2 Redis
A29: RT-04 | B29: Cache y Realtime | C29: Pub/Sub canal 'alertas' | D29: Como detector, quiero publicar alertas a un canal para que suscriptores las reciban en realtime. | E29: publish_alerta con payload JSON; multi-subscriber. | F29: P0 | G29: S | H29: Hecho | I29: v0.2 Redis
A30: RT-05 | B30: Cache y Realtime | C30: Endpoint SSE GET /alertas/stream | D30: Como frontend, quiero recibir push de alertas sin hacer polling. | E30: text/event-stream; auto-reconnect; heartbeat cada 15s. | F30: P0 | G30: M | H30: Hecho | I30: v0.2 Redis | J30: Probado con curl -N y demo HTML.
A31: RT-06 | B31: Cache y Realtime | C31: WebSocket bidireccional para comandos | D31: Como frontend, quiero mandar comandos al detector (ack, pausar, forzar analisis). | E31: WS /alertas/ws; protocolo de mensajes; auth via token en query. | F31: P2 | G31: L | H31: Pendiente | I31: v0.4 | J31: SSE ya cubre push; esto es para comandos.
A32: RT-07 | B32: Cache y Realtime | C32: Canales por sitio (multi-tenant) | D32: Como producto, quiero que cada cliente reciba solo las alertas de SUS camaras. | E32: Canal 'alertas:{sitio_id}'; el detector publica a canal especifico. | F32: P2 | G32: M | H32: Pendiente | I32: v0.5
A33: RT-08 | B33: Cache y Realtime | C33: Replay de ultimas N alertas al conectar | D33: Como frontend, quiero ver las ultimas alertas recientes al abrir el dashboard, no solo las nuevas. | E33: Sorted set en Redis con ultimas 50; se envian al conectar SSE. | F33: P1 | G33: M | H33: Pendiente | I33: v0.3
A34: NOT-01 | B34: Notificaciones | C34: Worker Telegram desacoplado | D34: Como sistema, quiero enviar alertas por Telegram sin bloquear al detector. | E34: Proceso separado; lee cola de notificaciones; retry con backoff. | F34: P0 | G34: M | H34: Hecho | I34: v0.1 MVP | J34: telegram_worker.py.
A35: NOT-02 | B35: Notificaciones | C35: Cola persistente en Postgres | D35: Como sistema, no quiero perder notificaciones si Telegram o el worker estan caidos. | E35: Tabla notificaciones con estado; worker polea cada N segundos. | F35: P0 | G35: M | H35: Hecho | I35: v0.1 MVP
A36: NOT-03 | B36: Notificaciones | C36: Retry con backoff ante fallos | D36: Como sistema, quiero reintentar envios fallidos (red, rate limit, etc). | E36: Max 3 intentos; backoff exponencial; marca como 'fallida' tras N fallos. | F36: P0 | G36: S | H36: Hecho | I36: v0.1 MVP
A37: NOT-04 | B37: Notificaciones | C37: Adjuntar snapshot al mensaje | D37: Como usuario, quiero ver la foto directamente en Telegram, no solo el texto. | E37: sendPhoto con snapshot descargado de MinIO; caption con info. | F37: P1 | G37: S | H37: Pendiente | I37: v0.2 | J37: Telegram permite hasta 10MB por foto.
A38: NOT-05 | B38: Notificaciones | C38: Botones inline (Reconocer/Descartar) | D38: Como usuario, quiero accionar la alerta desde Telegram sin abrir el dashboard. | E38: InlineKeyboardButton; callback al bot; update de alerta en DB. | F38: P1 | G38: M | H38: Pendiente | I38: v0.3 | J38: Requiere webhook o long polling.
A39: NOT-06 | B39: Notificaciones | C39: Bot conversacional | D39: Como usuario, quiero preguntarle al bot '/ultimas 5' y recibir resumen. | E39: Handler de comandos; queries a la DB; respuestas formateadas. | F39: P2 | G39: M | H39: Pendiente | I39: v0.4
A40: NOT-07 | B40: Notificaciones | C40: Canal Email (SMTP) | D40: Como admin, quiero recibir reportes diarios por email. | E40: Similar al worker de Telegram; templates HTML; configuracion SMTP. | F40: P2 | G40: M | H40: Pendiente | I40: v0.3
...

Sheet Resumen
A1: Camaras-IA - Resumen del Backlog
A3: Total items | B3: =COUNTA(Backlog!A2:A124) -> 123
A4: Hechos | B4: =COUNTIF(Backlog!H2:H124,"Hecho") -> 32
A5: En Progreso | B5: =COUNTIF(Backlog!H2:H124,"En Progreso") -> 1
A6: Pendientes | B6: =COUNTIF(Backlog!H2:H124,"Pendiente") -> 90
A7: % Completado | B7: =B4/B3 -> 0.2601626
A9: Por Epica
A10: Epica | B10: Total | C10: Hechos | D10: En Progreso | E10: Pendientes | F10: % Hecho | G10: P0 Pendientes
A11: Ingesta y Deteccion | B11: =COUNTIF(Backlog!B2:B124,A11) -> 10 | C11: =COUNTIFS(Backlog!B2:B124,A11,Backlog!H2:H124,"Hecho") -> 6 | D11: =COUNTIFS(Backlog!B2:B124,A11,Backlog!H2:H124,"En Progreso") -> 0 | E11: =COUNTIFS(Backlog!B2:B124,A11,Backlog!H2:H124,"Pendiente") -> 4 | F11: =IFERROR(C11/B11,0) -> 0.6 | G11: =COUNTIFS(Backlog!B2:B124,A11,Backlog!F2:F124,"P0",Backlog!H2:H124,"Pendiente") -> 0
A12: Analisis IA | B12: =COUNTIF(Backlog!B2:B124,A12) -> 7 | C12: =COUNTIFS(Backlog!B2:B124,A12,Backlog!H2:H124,"Hecho") -> 4 | D12: =COUNTIFS(Backlog!B2:B124,A12,Backlog!H2:H124,"En Progreso") -> 0 | E12: =COUNTIFS(Backlog!B2:B124,A12,Backlog!H2:H124,"Pendiente") -> 3 | F12: =IFERROR(C12/B12,0) -> 0.57142857 | G12: =COUNTIFS(Backlog!B2:B124,A12,Backlog!F2:F124,"P0",Backlog!H2:H124,"Pendiente") -> 0
A13: Storage | B13: =COUNTIF(Backlog!B2:B124,A13) -> 7 | C13: =COUNTIFS(Backlog!B2:B124,A13,Backlog!H2:H124,"Hecho") -> 3 | D13: =COUNTIFS(Backlog!B2:B124,A13,Backlog!H2:H124,"En Progreso") -> 0 | E13: =COUNTIFS(Backlog!B2:B124,A13,Backlog!H2:H124,"Pendiente") -> 4 | F13: =IFERROR(C13/B13,0) -> 0.42857143 | G13: =COUNTIFS(Backlog!B2:B124,A13,Backlog!F2:F124,"P0",Backlog!H2:H124,"Pendiente") -> 0
A14: Cache y Realtime | B14: =COUNTIF(Backlog!B2:B124,A14) -> 8 | C14: =COUNTIFS(Backlog!B2:B124,A14,Backlog!H2:H124,"Hecho") -> 5 | D14: =COUNTIFS(Backlog!B2:B124,A14,Backlog!H2:H124,"En Progreso") -> 0 | E14: =COUNTIFS(Backlog!B2:B124,A14,Backlog!H2:H124,"Pendiente") -> 3 | F14: =IFERROR(C14/B14,0) -> 0.625 | G14: =COUNTIFS(Backlog!B2:B124,A14,Backlog!F2:F124,"P0",Backlog!H2:H124,"Pendiente") -> 0
A15: Notificaciones | B15: =COUNTIF(Backlog!B2:B124,A15) -> 9 | C15: =COUNTIFS(Backlog!B2:B124,A15,Backlog!H2:H124,"Hecho") -> 3 | D15: =COUNTIFS(Backlog!B2:B124,A15,Backlog!H2:H124,"En Progreso") -> 0 | E15: =COUNTIFS(Backlog!B2:B124,A15,Backlog!H2:H124,"Pendiente") -> 6 | F15: =IFERROR(C15/B15,0) -> 0.33333333 | G15: =COUNTIFS(Backlog!B2:B124,A15,Backlog!F2:F124,"P0",Backlog!H2:H124,"Pendiente") -> 0
A16: API REST | B16: =COUNTIF(Backlog!B2:B124,A16) -> 10 | C16: =COUNTIFS(Backlog!B2:B124,A16,Backlog!H2:H124,"Hecho") -> 4 | D16: =COUNTIFS(Backlog!B2:B124,A16,Backlog!H2:H124,"En Progreso") -> 0 | E16: =COUNTIFS(Backlog!B2:B124,A16,Backlog!H2:H124,"Pendiente") -> 6 | F16: =IFERROR(C16/B16,0) -> 0.4 | G16: =COUNTIFS(Backlog!B2:B124,A16,Backlog!F2:F124,"P0",Backlog!H2:H124,"Pendiente") -> 1
A17: Frontend | B17: =COUNTIF(Backlog!B2:B124,A17) -> 10 | C17: =COUNTIFS(Backlog!B2:B124,A17,Backlog!H2:H124,"Hecho") -> 0 | D17: =COUNTIFS(Backlog!B2:B124,A17,Backlog!H2:H124,"En Progreso") -> 1 | E17: =COUNTIFS(Backlog!B2:B124,A17,Backlog!H2:H124,"Pendiente") -> 9 | F17: =IFERROR(C17/B17,0) -> 0 | G17: =COUNTIFS(Backlog!B2:B124,A17,Backlog!F2:F124,"P0",Backlog!H2:H124,"Pendiente") -> 5
A18: Autenticacion | B18: =COUNTIF(Backlog!B2:B124,A18) -> 9 | C18: =COUNTIFS(Backlog!B2:B124,A18,Backlog!H2:H124,"Hecho") -> 0 | D18: =COUNTIFS(Backlog!B2:B124,A18,Backlog!H2:H124,"En Progreso") -> 0 | E18: =COUNTIFS(Backlog!B2:B124,A18,Backlog!H2:H124,"Pendiente") -> 9 | F18: =IFERROR(C18/B18,0) -> 0 | G18: =COUNTIFS(Backlog!B2:B124,A18,Backlog!F2:F124,"P0",Backlog!H2:H124,"Pendiente") -> 4
A19: Admin Camaras | B19: =COUNTIF(Backlog!B2:B124,A19) -> 6 | C19: =COUNTIFS(Backlog!B2:B124,A19,Backlog!H2:H124,"Hecho") -> 0 | D19: =COUNTIFS(Backlog!B2:B124,A19,Backlog!H2:H124,"En Progreso") -> 0 | E19: =COUNTIFS(Backlog!B2:B124,A19,Backlog!H2:H124,"Pendiente") -> 6 | F19: =IFERROR(C19/B19,0) -> 0 | G19: =COUNTIFS(Backlog!B2:B124,A19,Backlog!F2:F124,"P0",Backlog!H2:H124,"Pendiente") -> 1
A20: Admin General | B20: =COUNTIF(Backlog!B2:B124,A20) -> 5 | C20: =COUNTIFS(Backlog!B2:B124,A20,Backlog!H2:H124,"Hecho") -> 0 | D20: =COUNTIFS(Backlog!B2:B124,A20,Backlog!H2:H124,"En Progreso") -> 0 | E20: =COUNTIFS(Backlog!B2:B124,A20,Backlog!H2:H124,"Pendiente") -> 5 | F20: =IFERROR(C20/B20,0) -> 0 | G20: =COUNTIFS(Backlog!B2:B124,A20,Backlog!F2:F124,"P0",Backlog!H2:H124,"Pendiente") -> 1
A21: Analitica | B21: =COUNTIF(Backlog!B2:B124,A21) -> 5 | C21: =COUNTIFS(Backlog!B2:B124,A21,Backlog!H2:H124,"Hecho") -> 0 | D21: =COUNTIFS(Backlog!B2:B124,A21,Backlog!H2:H124,"En Progreso") -> 0 | E21: =COUNTIFS(Backlog!B2:B124,A21,Backlog!H2:H124,"Pendiente") -> 5 | F21: =IFERROR(C21/B21,0) -> 0 | G21: =COUNTIFS(Backlog!B2:B124,A21,Backlog!F2:F124,"P0",Backlog!H2:H124,"Pendiente") -> 0
A22: Observabilidad | B22: =COUNTIF(Backlog!B2:B124,A22) -> 7 | C22: =COUNTIFS(Backlog!B2:B124,A22,Backlog!H2:H124,"Hecho") -> 2 | D22: =COUNTIFS(Backlog!B2:B124,A22,Backlog!H2:H124,"En Progreso") -> 0 | E22: =COUNTIFS(Backlog!B2:B124,A22,Backlog!H2:H124,"Pendiente") -> 5 | F22: =IFERROR(C22/B22,0) -> 0.28571429 | G22: =COUNTIFS(Backlog!B2:B124,A22,Backlog!F2:F124,"P0",Backlog!H2:H124,"Pendiente") -> 0
A23: DevOps | B23: =COUNTIF(Backlog!B2:B124,A23) -> 8 | C23: =COUNTIFS(Backlog!B2:B124,A23,Backlog!H2:H124,"Hecho") -> 1 | D23: =COUNTIFS(Backlog!B2:B124,A23,Backlog!H2:H124,"En Progreso") -> 0 | E23: =COUNTIFS(Backlog!B2:B124,A23,Backlog!H2:H124,"Pendiente") -> 7 | F23: =IFERROR(C23/B23,0) -> 0.125 | G23: =COUNTIFS(Backlog!B2:B124,A23,Backlog!F2:F124,"P0",Backlog!H2:H124,"Pendiente") -> 0
A24: Seguridad | B24: =COUNTIF(Backlog!B2:B124,A24) -> 8 | C24: =COUNTIFS(Backlog!B2:B124,A24,Backlog!H2:H124,"Hecho") -> 2 | D24: =COUNTIFS(Backlog!B2:B124,A24,Backlog!H2:H124,"En Progreso") -> 0 | E24: =COUNTIFS(Backlog!B2:B124,A24,Backlog!H2:H124,"Pendiente") -> 6 | F24: =IFERROR(C24/B24,0) -> 0.25 | G24: =COUNTIFS(Backlog!B2:B124,A24,Backlog!F2:F124,"P0",Backlog!H2:H124,"Pendiente") -> 1
A25: Testing | B25: =COUNTIF(Backlog!B2:B124,A25) -> 6 | C25: =COUNTIFS(Backlog!B2:B124,A25,Backlog!H2:H124,"Hecho") -> 0 | D25: =COUNTIFS(Backlog!B2:B124,A25,Backlog!H2:H124,"En Progreso") -> 0 | E25: =COUNTIFS(Backlog!B2:B124,A25,Backlog!H2:H124,"Pendiente") -> 6 | F25: =IFERROR(C25/B25,0) -> 0 | G25: =COUNTIFS(Backlog!B2:B124,A25,Backlog!F2:F124,"P0",Backlog!H2:H124,"Pendiente") -> 0
A26: Documentacion | B26: =COUNTIF(Backlog!B2:B124,A26) -> 8 | C26: =COUNTIFS(Backlog!B2:B124,A26,Backlog!H2:H124,"Hecho") -> 2 | D26: =COUNTIFS(Backlog!B2:B124,A26,Backlog!H2:H124,"En Progreso") -> 0 | E26: =COUNTIFS(Backlog!B2:B124,A26,Backlog!H2:H124,"Pendiente") -> 6 | F26: =IFERROR(C26/B26,0) -> 0.25 | G26: =COUNTIFS(Backlog!B2:B124,A26,Backlog!F2:F124,"P0",Backlog!H2:H124,"Pendiente") -> 0
A27: TOTAL | B27: =SUM(B11:B26) -> 123 | C27: =SUM(C11:C26) -> 32 | D27: =SUM(D11:D26) -> 1 | E27: =SUM(E11:E26) -> 90 | F27: =IFERROR(C27/B27,0) -> 0.2601626 | G27: =SUM(G11:G26) -> 13

Sheet Guia
A1: Guia del Backlog - Camaras-IA
A3: Columnas del backlog
A4: ID | B4: Identificador unico. Prefijo por epica (ING-, IA-, RT-, etc).
A5: Epica | B5: Agrupacion funcional de items relacionados.
A6: Historia de Usuario | B6: Formato: Como <rol>, quiero <accion> para <beneficio>.
A7: Criterios | B7: Condiciones que deben cumplirse para considerar el item 'hecho'.
A8: Prioridad | B8: P0 = Must (critico/bloqueante), P1 = Should, P2 = Could, P3 = Later.
A9: Estimacion | B9: S = 1-2 dias, M = 3-5 dias, L = 1-2 semanas, XL = 3+ semanas.
A10: Estado | B10: Hecho | En Progreso | Pendiente.
A11: Release | B11: Sugerencia tentativa de en que version/sprint entra.
A13: Convencion de releases
A14: v0.1 MVP | B14: Detector + DB + MinIO + API + Telegram (ya entregado).
A15: v0.2 Redis | B15: Cache + pub/sub + SSE (ya entregado).
A16: v0.3 Auth | B16: Autenticacion + CRUD basico + frontend integrado.
A17: v0.4 | B17: Administracion completa + analitica + docker.
A18: v0.5 | B18: Deploy produccion + HTTPS + testing + multi-tenant.
A19: v0.6+ | B19: Refinamiento + observabilidad avanzada.
A20: v1.0 | B20: Producto listo para ventas/clientes reales.
A22: Como usar este documento
A23: 1 | B23: Usar el auto-filter de la hoja Backlog para filtrar por prioridad, epica o estado.
A24: 2 | B24: Trabajar primero los P0 pendientes (columna resaltada en la hoja Resumen).
A25: 3 | B25: Actualizar la columna 'Estado' a medida que avanzas.
A26: 4 | B26: Las formulas de la hoja Resumen se actualizan solas.
A27: 5 | B27: Agregar items nuevos al final de la hoja Backlog con ID siguiente disponible.
